Workbook
Name MTC: 'RORO_Stage_Scenarios'!$B$9
Name LCF: 'RORO_Stage_Scenarios'!$B$10
Name PumpRate: 'RORO_Stage_Scenarios'!$B$13
Name X_Ballast: 'RORO_Stage_Scenarios'!$B$14
Name TRIM5_CM: 'RORO_Stage_Scenarios'!$E$23

Sheet Calc
B2: LCT BUSHRA — RORO Calculator & Limits
B3: SECTION | C3: PARAMETER | D3: UNIT | E3: VALUE | F3: NOTES
B5: INPUT CONSTANTS | C5: L_ramp_m | D5: m | E5: 12 | F5: Linkspan length. Calc!D4
C6: theta_max_deg | D6: deg | E6: 6 | F6: Max ramp angle. Calc!D5
C7: KminusZ_m | D7: m | E7: 3 | F7: K - Z (UPDATE!). Calc!D6
C8: D_vessel_m | D8: m | E8: 3.65 | F8: Molded depth. Calc!D7
B10: LIMITS & OPS | C10: min_fwd_draft_m | D10: m | E10: 1.5 | F10: Min draft. Calc!D9
C11: max_fwd_draft_m | D11: m | E11: 3.5 | F11: Max draft. Calc!D10
C12: pump_rate_tph | D12: t/h | E12: 10 | F12: Pump rate. Calc!D11
B14: STABILITY | C14: MTC_t_m_per_cm | D14: t·m/cm | E14: 34 | F14: MTC. Calc!D13
C15: LCF_m_from_midship | D15: m | E15: 0.76 | F15: LCF from Midship (Corrected). Calc!D14
C16: TPC_t_per_cm | D16: t/cm | E16: 8 | F16: TPC. Calc!D15
C17: Lpp_m | D17: m | E17: 60.302 | F17: Length between perpendiculars. Calc!D16
B18: OPERATIONS | C18: max_fwd_draft_ops_m | D18: m | E18: 2.7 | F18: Max forward draft for operations. Calc!D9
C19: ramp_door_offset_m | D19: m | E19: 0.15 | F19: Ramp door offset. Calc!D11
C20: linkspan_freeboard_target_m | D20: m | E20: 0.28 | F20: Linkspan freeboard target. Calc!D12
C21: gm_target_m | D21: m | E21: 1.5 | F21: GM target. Calc!D13
B23: STRUCTURAL LIMITS | C23: limit_reaction_t | D23: t | E23: 201.6 | F23: Aries Ramp hinge limit 201.60 t (share ratio 0.545, 2025-11-18)
C24: limit_share_load_t | D24: t | E24: 118.8 | F24: Max Share Load on LCT (Mammoet)
C25: limit_deck_press_tpm2 | D25: t/m² | E25: 10 | F25: Max Deck Pressure (Spec)
C26: linkspan_area_m2 | D26: m² | E26: 12 | F26: Linkspan 실제 접지 12.00 m² (Ramp 1 TR only 규정)
B27: BALLAST FIX CHECK | C27: max_aft_ballast_cap_t | D27: t | E27: 28 | F27: Max AFT Ballast Capacity (FW2 P/S, Fr 0–6, ~28t)
C28: max_fwd_ballast_cap_t | D28: t | E28: 321 | F28: Max Forward Ballast Capacity (FWB1/2, Fr 48–65, ~321t)
C29: max_pump_time_h | D29: h | E29: 6 | F29: Max Allowed Pump Time for Fix
B30: VENT & PUMP | C30: vent_flow_coeff | D30: t/h per mm | E30: 0.86 | F30: 실측 보정 0.86 (2025-11-18, MAPE 0.30%)
C31: pump_rate_tph | D31: t/h | E31: 100 | F31: Hired pump rate
C32: pump_rate_effective_tph | D32: t/h | E32: =MIN(E31, SUMPRODUCT((Ballast_Tanks!E$2:E$100="Y")*(Ballast_Tanks!F$2:F$100)*E30)) | F32: 실효 펌프 속도 (vent bottleneck, 68.80 t/h)
B33: RAMP GEOMETRY | C33: ramp_hinge_x_mid_m | D33: m | E33: -30.151 | F33: LBP 60.302 m 기준
C34: ramp_length_m | D34: m | E34: 8.3 | F34: TRE Cert 2020-08-04
C35: linkspan_height_m | D35: m | E35: 2
C36: ramp_end_clearance_min_m | D36: m | E36: 0.4
B37: HINGE STRESS | C37: hinge_pin_area_m2 | D37: m² | E37: 0.117 | F37: Doubler 390x300 mm (Aries)
C38: hinge_limit_rx_t | D38: t | E38: 201.6 | F38: Max Hinge Reaction (duplicate of E23 for clarity)
B40: PRECISION PARAMETERS
C41: LBP_m | D41: m | E41: 60.302 | F41: Length Between Perpendiculars (for precise draft calculation)
C42: LCF_from_mid_m | D42: m | E42: 0.76 | F42: LCF from midship (BUSHRA verified, for precise draft calculation)
C43: dynamic_factor | D43: - | E43: 1.15 | F43: Dynamic load amplification factor (for Load Case B)
C44: heel_y_offset_m | D44: m | E44: 1.5 | F44: Heel y-offset (for heel angle calculation)

Sheet December_Tide_2025
A1: datetime_gst | B1: tide_m (Chart Datum)

Sheet Hourly_FWD_AFT_Heights
A1: DateTime (GST) | B1: Tide_m | C1: Dfwd_req_m (even) | D1: Trim_m (optional) | E1: Dfwd_adj_m | F1: Daft_adj_m | G1: Ramp_Angle_deg | H1: Status | I1: FWD_Height_m | J1: AFT_Height_m | K1: Notes | M1: Trim_m (optional)
A2: =IF(December_Tide_2025!A2="","",December_Tide_2025!A2) | B2: =IF(December_Tide_2025!B2="","",December_Tide_2025!B2) | C2: =IF($A2="","", INDEX(Calc!$E:$E, MATCH("KminusZ_m", Calc!$C:$C, 0)) + $B2 - INDEX(Calc!$E:$E, MATCH("L_ramp_m", Calc!$C:$C, 0)) * TAN(RADIANS(INDEX(Calc!$E:$E, MATCH("theta_max_deg", Calc!$C:$C, 0))))) | E2: =IF($C2="","", IF($D2="", $C2, $C2 - $D2/2)) | F2: =IF($C2="","", IF($D2="", $C2, $C2 + $D2/2)) | G2: =IF($E2="","", DEGREES(ATAN((INDEX(Calc!$E:$E, MATCH("KminusZ_m", Calc!$C:$C, 0)) - $E2 + $B2) / INDEX(Calc!$E:$E, MATCH("L_ramp_m", Calc!$C:$C, 0))))) | H2: =IF($E2="","", IF(AND($E2>=INDEX(Calc!$E:$E, MATCH("min_fwd_draft_m", Calc!$C:$C, 0)), $E2<=INDEX(Calc!$E:$E, MATCH("max_fwd_draft_m", Calc!$C:$C, 0)), $G2<=INDEX(Calc!$E:$E, MATCH("theta_max_deg", Calc!$C:$C, 0))), "OK", "CHECK")) | I2: =IF($E2="","", INDEX(Calc!$E:$E, MATCH("D_vessel_m", Calc!$C:$C, 0)) - $E2 + $B2) | J2: =IF($F2="","", INDEX(Calc!$E:$E, MATCH("D_vessel_m", Calc!$C:$C, 0)) - $F2 + $B2) | K2: =IF(D2=0, "Even Keel", "") | N2: ← Defaults to 0.00 (Even-Keel). To apply the actual trim, manually enter the value in this cell.
A3: =IF(December_Tide_2025!A3="","",December_Tide_2025!A3) | B3: =IF(December_Tide_2025!B3="","",December_Tide_2025!B3) | C3: =IF($A3="","", INDEX(Calc!$E:$E, MATCH("KminusZ_m", Calc!$C:$C, 0)) + $B3 - INDEX(Calc!$E:$E, MATCH("L_ramp_m", Calc!$C:$C, 0)) * TAN(RADIANS(INDEX(Calc!$E:$E, MATCH("theta_max_deg", Calc!$C:$C, 0))))) | E3: =IF($C3="","", IF($D3="", $C3, $C3 - $D3/2)) | F3: =IF($C3="","", IF($D3="", $C3, $C3 + $D3/2)) | G3: =IF($E3="","", DEGREES(ATAN((INDEX(Calc!$E:$E, MATCH("KminusZ_m", Calc!$C:$C, 0)) - $E3 + $B3) / INDEX(Calc!$E:$E, MATCH("L_ramp_m", Calc!$C:$C, 0))))) | H3: =IF($E3="","", IF(AND($E3>=INDEX(Calc!$E:$E, MATCH("min_fwd_draft_m", Calc!$C:$C, 0)), $E3<=INDEX(Calc!$E:$E, MATCH("max_fwd_draft_m", Calc!$C:$C, 0)), $G3<=INDEX(Calc!$E:$E, MATCH("theta_max_deg", Calc!$C:$C, 0))), "OK", "CHECK")) | I3: =IF($E3="","", INDEX(Calc!$E:$E, MATCH("D_vessel_m", Calc!$C:$C, 0)) - $E3 + $B3) | J3: =IF($F3="","", INDEX(Calc!$E:$E, MATCH("D_vessel_m", Calc!$C:$C, 0)) - $F3 + $B3) | K3: =IF(D3=0, "Even Keel", "")
A4: =IF(December_Tide_2025!A4="","",December_Tide_2025!A4) | B4: =IF(December_Tide_2025!B4="","",December_Tide_2025!B4) | C4: =IF($A4="","", INDEX(Calc!$E:$E, MATCH("KminusZ_m", Calc!$C:$C, 0)) + $B4 - INDEX(Calc!$E:$E, MATCH("L_ramp_m", Calc!$C:$C, 0)) * TAN(RADIANS(INDEX(Calc!$E:$E, MATCH("theta_max_deg", Calc!$C:$C, 0))))) | E4: =IF($C4="","", IF($D4="", $C4, $C4 - $D4/2)) | F4: =IF($C4="","", IF($D4="", $C4, $C4 + $D4/2)) | G4: =IF($E4="","", DEGREES(ATAN((INDEX(Calc!$E:$E, MATCH("KminusZ_m", Calc!$C:$C, 0)) - $E4 + $B4) / INDEX(Calc!$E:$E, MATCH("L_ramp_m", Calc!$C:$C, 0))))) | H4: =IF($E4="","", IF(AND($E4>=INDEX(Calc!$E:$E, MATCH("min_fwd_draft_m", Calc!$C:$C, 0)), $E4<=INDEX(Calc!$E:$E, MATCH("max_fwd_draft_m", Calc!$C:$C, 0)), $G4<=INDEX(Calc!$E:$E, MATCH("theta_max_deg", Calc!$C:$C, 0))), "OK", "CHECK")) | I4: =IF($E4="","", INDEX(Calc!$E:$E, MATCH("D_vessel_m", Calc!$C:$C, 0)) - $E4 + $B4) | J4: =IF($F4="","", INDEX(Calc!$E:$E, MATCH("D_vessel_m", Calc!$C:$C, 0)) - $F4 + $B4) | K4: =IF(D4=0, "Even Keel", "")
A5: =IF(December_Tide_2025!A5="","",December_Tide_2025!A5) | B5: =IF(December_Tide_2025!B5="","",December_Tide_2025!B5) | C5: =IF($A5="","", INDEX(Calc!$E:$E, MATCH("KminusZ_m", Calc!$C:$C, 0)) + $B5 - INDEX(Calc!$E:$E, MATCH("L_ramp_m", Calc!$C:$C, 0)) * TAN(RADIANS(INDEX(Calc!$E:$E, MATCH("theta_max_deg", Calc!$C:$C, 0))))) | E5: =IF($C5="","", IF($D5="", $C5, $C5 - $D5/2)) | F5: =IF($C5="","", IF($D5="", $C5, $C5 + $D5/2)) | G5: =IF($E5="","", DEGREES(ATAN((INDEX(Calc!$E:$E, MATCH("KminusZ_m", Calc!$C:$C, 0)) - $E5 + $B5) / INDEX(Calc!$E:$E, MATCH("L_ramp_m", Calc!$C:$C, 0))))) | H5: =IF($E5="","", IF(AND($E5>=INDEX(Calc!$E:$E, MATCH("min_fwd_draft_m", Calc!$C:$C, 0)), $E5<=INDEX(Calc!$E:$E, MATCH("max_fwd_draft_m", Calc!$C:$C, 0)), $G5<=INDEX(Calc!$E:$E, MATCH("theta_max_deg", Calc!$C:$C, 0))), "OK", "CHECK")) | I5: =IF($E5="","", INDEX(Calc!$E:$E, MATCH("D_vessel_m", Calc!$C:$C, 0)) - $E5 + $B5) | J5: =IF($F5="","", INDEX(Calc!$E:$E, MATCH("D_vessel_m", Calc!$C:$C, 0)) - $F5 + $B5) | K5: =IF(D5=0, "Even Keel", "")
A6: =IF(December_Tide_2025!A6="","",December_Tide_2025!A6) | B6: =IF(December_Tide_2025!B6="","",December_Tide_2025!B6) | C6: =IF($A6="","", INDEX(Calc!$E:$E, MATCH("KminusZ_m", Calc!$C:$C, 0)) + $B6 - INDEX(Calc!$E:$E, MATCH("L_ramp_m", Calc!$C:$C, 0)) * TAN(RADIANS(INDEX(Calc!$E:$E, MATCH("theta_max_deg", Calc!$C:$C, 0))))) | E6: =IF($C6="","", IF($D6="", $C6, $C6 - $D6/2)) | F6: =IF($C6="","", IF($D6="", $C6, $C6 + $D6/2)) | G6: =IF($E6="","", DEGREES(ATAN((INDEX(Calc!$E:$E, MATCH("KminusZ_m", Calc!$C:$C, 0)) - $E6 + $B6) / INDEX(Calc!$E:$E, MATCH("L_ramp_m", Calc!$C:$C, 0))))) | H6: =IF($E6="","", IF(AND($E6>=INDEX(Calc!$E:$E, MATCH("min_fwd_draft_m", Calc!$C:$C, 0)), $E6<=INDEX(Calc!$E:$E, MATCH("max_fwd_draft_m", Calc!$C:$C, 0)), $G6<=INDEX(Calc!$E:$E, MATCH("theta_max_deg", Calc!$C:$C, 0))), "OK", "CHECK")) | I6: =IF($E6="","", INDEX(Calc!$E:$E, MATCH("D_vessel_m", Calc!$C:$C, 0)) - $E6 + $B6) | J6: =IF($F6="","", INDEX(Calc!$E:$E, MATCH("D_vessel_m", Calc!$C:$C, 0)) - $F6 + $B6) | K6: =IF(D6=0, "Even Keel", "")
A7: =IF(December_Tide_2025!A7="","",December_Tide_2025!A7) | B7: =IF(December_Tide_2025!B7="","",December_Tide_2025!B7) | C7: =IF($A7="","", INDEX(Calc!$E:$E, MATCH("KminusZ_m", Calc!$C:$C, 0)) + $B7 - INDEX(Calc!$E:$E, MATCH("L_ramp_m", Calc!$C:$C, 0)) * TAN(RADIANS(INDEX(Calc!$E:$E, MATCH("theta_max_deg", Calc!$C:$C, 0))))) | E7: =IF($C7="","", IF($D7="", $C7, $C7 - $D7/2)) | F7: =IF($C7="","", IF($D7="", $C7, $C7 + $D7/2)) | G7: =IF($E7="","", DEGREES(ATAN((INDEX(Calc!$E:$E, MATCH("KminusZ_m", Calc!$C:$C, 0)) - $E7 + $B7) / INDEX(Calc!$E:$E, MATCH("L_ramp_m", Calc!$C:$C, 0))))) | H7: =IF($E7="","", IF(AND($E7>=INDEX(Calc!$E:$E, MATCH("min_fwd_draft_m", Calc!$C:$C, 0)), $E7<=INDEX(Calc!$E:$E, MATCH("max_fwd_draft_m", Calc!$C:$C, 0)), $G7<=INDEX(Calc!$E:$E, MATCH("theta_max_deg", Calc!$C:$C, 0))), "OK", "CHECK")) | I7: =IF($E7="","", INDEX(Calc!$E:$E, MATCH("D_vessel_m", Calc!$C:$C, 0)) - $E7 + $B7) | J7: =IF($F7="","", INDEX(Calc!$E:$E, MATCH("D_vessel_m", Calc!$C:$C, 0)) - $F7 + $B7) | K7: =IF(D7=0, "Even Keel", "")
A8: =IF(December_Tide_2025!A8="","",December_Tide_2025!A8) | B8: =IF(December_Tide_2025!B8="","",December_Tide_2025!B8) | C8: =IF($A8="","", INDEX(Calc!$E:$E, MATCH("KminusZ_m", Calc!$C:$C, 0)) + $B8 - INDEX(Calc!$E:$E, MATCH("L_ramp_m", Calc!$C:$C, 0)) * TAN(RADIANS(INDEX(Calc!$E:$E, MATCH("theta_max_deg", Calc!$C:$C, 0))))) | E8: =IF($C8="","", IF($D8="", $C8, $C8 - $D8/2)) | F8: =IF($C8="","", IF($D8="", $C8, $C8 + $D8/2)) | G8: =IF($E8="","", DEGREES(ATAN((INDEX(Calc!$E:$E, MATCH("KminusZ_m", Calc!$C:$C, 0)) - $E8 + $B8) / INDEX(Calc!$E:$E, MATCH("L_ramp_m", Calc!$C:$C, 0))))) | H8: =IF($E8="","", IF(AND($E8>=INDEX(Calc!$E:$E, MATCH("min_fwd_draft_m", Calc!$C:$C, 0)), $E8<=INDEX(Calc!$E:$E, MATCH("max_fwd_draft_m", Calc!$C:$C, 0)), $G8<=INDEX(Calc!$E:$E, MATCH("theta_max_deg", Calc!$C:$C, 0))), "OK", "CHECK")) | I8: =IF($E8="","", INDEX(Calc!$E:$E, MATCH("D_vessel_m", Calc!$C:$C, 0)) - $E8 + $B8) | J8: =IF($F8="","", INDEX(Calc!$E:$E, MATCH("D_vessel_m", Calc!$C:$C, 0)) - $F8 + $B8) | K8: =IF(D8=0, "Even Keel", "")
A9: =IF(December_Tide_2025!A9="","",December_Tide_2025!A9) | B9: =IF(December_Tide_2025!B9="","",December_Tide_2025!B9) | C9: =IF($A9="","", INDEX(Calc!$E:$E, MATCH("KminusZ_m", Calc!$C:$C, 0)) + $B9 - INDEX(Calc!$E:$E, MATCH("L_ramp_m", Calc!$C:$C, 0)) * TAN(RADIANS(INDEX(Calc!$E:$E, MATCH("theta_max_deg", Calc!$C:$C, 0))))) | E9: =IF($C9="","", IF($D9="", $C9, $C9 - $D9/2)) | F9: =IF($C9="","", IF($D9="", $C9, $C9 + $D9/2)) | G9: =IF($E9="","", DEGREES(ATAN((INDEX(Calc!$E:$E, MATCH("KminusZ_m", Calc!$C:$C, 0)) - $E9 + $B9) / INDEX(Calc!$E:$E, MATCH("L_ramp_m", Calc!$C:$C, 0))))) | H9: =IF($E9="","", IF(AND($E9>=INDEX(Calc!$E:$E, MATCH("min_fwd_draft_m", Calc!$C:$C, 0)), $E9<=INDEX(Calc!$E:$E, MATCH("max_fwd_draft_m", Calc!$C:$C, 0)), $G9<=INDEX(Calc!$E:$E, MATCH("theta_max_deg", Calc!$C:$C, 0))), "OK", "CHECK")) | I9: =IF($E9="","", INDEX(Calc!$E:$E, MATCH("D_vessel_m", Calc!$C:$C, 0)) - $E9 + $B9) | J9: =IF($F9="","", INDEX(Calc!$E:$E, MATCH("D_vessel_m", Calc!$C:$C, 0)) - $F9 + $B9) | K9: =IF(D9=0, "Even Keel", "")
A10: =IF(December_Tide_2025!A10="","",December_Tide_2025!A10) | B10: =IF(December_Tide_2025!B10="","",December_Tide_2025!B10) | C10: =IF($A10="","", INDEX(Calc!$E:$E, MATCH("KminusZ_m", Calc!$C:$C, 0)) + $B10 - INDEX(Calc!$E:$E, MATCH("L_ramp_m", Calc!$C:$C, 0)) * TAN(RADIANS(INDEX(Calc!$E:$E, MATCH("theta_max_deg", Calc!$C:$C, 0))))) | E10: =IF($C10="","", IF($D10="", $C10, $C10 - $D10/2)) | F10: =IF($C10="","", IF($D10="", $C10, $C10 + $D10/2)) | G10: =IF($E10="","", DEGREES(ATAN((INDEX(Calc!$E:$E, MATCH("KminusZ_m", Calc!$C:$C, 0)) - $E10 + $B10) / INDEX(Calc!$E:$E, MATCH("L_ramp_m", Calc!$C:$C, 0))))) | H10: =IF($E10="","", IF(AND($E10>=INDEX(Calc!$E:$E, MATCH("min_fwd_draft_m", Calc!$C:$C, 0)), $E10<=INDEX(Calc!$E:$E, MATCH("max_fwd_draft_m", Calc!$C:$C, 0)), $G10<=INDEX(Calc!$E:$E, MATCH("theta_max_deg", Calc!$C:$C, 0))), "OK", "CHECK")) | I10: =IF($E10="","", INDEX(Calc!$E:$E, MATCH("D_vessel_m", Calc!$C:$C, 0)) - $E10 + $B10) | J10: =IF($F10="","", INDEX(Calc!$E:$E, MATCH("D_vessel_m", Calc!$C:$C, 0)) - $F10 + $B10) | K10: =IF(D10=0, "Even Keel", "")
A11: =IF(December_Tide_2025!A11="","",December_Tide_2025!A11) | B11: =IF(December_Tide_2025!B11="","",December_Tide_2025!B11) | C11: =IF($A11="","", INDEX(Calc!$E:$E, MATCH("KminusZ_m", Calc!$C:$C, 0)) + $B11 - INDEX(Calc!$E:$E, MATCH("L_ramp_m", Calc!$C:$C, 0)) * TAN(RADIANS(INDEX(Calc!$E:$E, MATCH("theta_max_deg", Calc!$C:$C, 0))))) | E11: =IF($C11="","", IF($D11="", $C11, $C11 - $D11/2)) | F11: =IF($C11="","", IF($D11="", $C11, $C11 + $D11/2)) | G11: =IF($E11="","", DEGREES(ATAN((INDEX(Calc!$E:$E, MATCH("KminusZ_m", Calc!$C:$C, 0)) - $E11 + $B11) / INDEX(Calc!$E:$E, MATCH("L_ramp_m", Calc!$C:$C, 0))))) | H11: =IF($E11="","", IF(AND($E11>=INDEX(Calc!$E:$E, MATCH("min_fwd_draft_m", Calc!$C:$C, 0)), $E11<=INDEX(Calc!$E:$E, MATCH("max_fwd_draft_m", Calc!$C:$C, 0)), $G11<=INDEX(Calc!$E:$E, MATCH("theta_max_deg", Calc!$C:$C, 0))), "OK", "CHECK")) | I11: =IF($E11="","", INDEX(Calc!$E:$E, MATCH("D_vessel_m", Calc!$C:$C, 0)) - $E11 + $B11) | J11: =IF($F11="","", INDEX(Calc!$E:$E, MATCH("D_vessel_m", Calc!$C:$C, 0)) - $F11 + $B11) | K11: =IF(D11=0, "Even Keel", "")
A12: =IF(December_Tide_2025!A12="","",December_Tide_2025!A12) | B12: =IF(December_Tide_2025!B12="","",December_Tide_2025!B12) | C12: =IF($A12="","", INDEX(Calc!$E:$E, MATCH("KminusZ_m", Calc!$C:$C, 0)) + $B12 - INDEX(Calc!$E:$E, MATCH("L_ramp_m", Calc!$C:$C, 0)) * TAN(RADIANS(INDEX(Calc!$E:$E, MATCH("theta_max_deg", Calc!$C:$C, 0))))) | E12: =IF($C12="","", IF($D12="", $C12, $C12 - $D12/2)) | F12: =IF($C12="","", IF($D12="", $C12, $C12 + $D12/2)) | G12: =IF($E12="","", DEGREES(ATAN((INDEX(Calc!$E:$E, MATCH("KminusZ_m", Calc!$C:$C, 0)) - $E12 + $B12) / INDEX(Calc!$E:$E, MATCH("L_ramp_m", Calc!$C:$C, 0))))) | H12: =IF($E12="","", IF(AND($E12>=INDEX(Calc!$E:$E, MATCH("min_fwd_draft_m", Calc!$C:$C, 0)), $E12<=INDEX(Calc!$E:$E, MATCH("max_fwd_draft_m", Calc!$C:$C, 0)), $G12<=INDEX(Calc!$E:$E, MATCH("theta_max_deg", Calc!$C:$C, 0))), "OK", "CHECK")) | I12: =IF($E12="","", INDEX(Calc!$E:$E, MATCH("D_vessel_m", Calc!$C:$C, 0)) - $E12 + $B12) | J12: =IF($F12="","", INDEX(Calc!$E:$E, MATCH("D_vessel_m", Calc!$C:$C, 0)) - $F12 + $B12) | K12: =IF(D12=0, "Even Keel", "")
A13: =IF(December_Tide_2025!A13="","",December_Tide_2025!A13) | B13: =IF(December_Tide_2025!B13="","",December_Tide_2025!B13) | C13: =IF($A13="","", INDEX(Calc!$E:$E, MATCH("KminusZ_m", Calc!$C:$C, 0)) + $B13 - INDEX(Calc!$E:$E, MATCH("L_ramp_m", Calc!$C:$C, 0)) * TAN(RADIANS(INDEX(Calc!$E:$E, MATCH("theta_max_deg", Calc!$C:$C, 0))))) | E13: =IF($C13="","", IF($D13="", $C13, $C13 - $D13/2)) | F13: =IF($C13="","", IF($D13="", $C13, $C13 + $D13/2)) | G13: =IF($E13="","", DEGREES(ATAN((INDEX(Calc!$E:$E, MATCH("KminusZ_m", Calc!$C:$C, 0)) - $E13 + $B13) / INDEX(Calc!$E:$E, MATCH("L_ramp_m", Calc!$C:$C, 0))))) | H13: =IF($E13="","", IF(AND($E13>=INDEX(Calc!$E:$E, MATCH("min_fwd_draft_m", Calc!$C:$C, 0)), $E13<=INDEX(Calc!$E:$E, MATCH("max_fwd_draft_m", Calc!$C:$C, 0)), $G13<=INDEX(Calc!$E:$E, MATCH("theta_max_deg", Calc!$C:$C, 0))), "OK", "CHECK")) | I13: =IF($E13="","", INDEX(Calc!$E:$E, MATCH("D_vessel_m", Calc!$C:$C, 0)) - $E13 + $B13) | J13: =IF($F13="","", INDEX(Calc!$E:$E, MATCH("D_vessel_m", Calc!$C:$C, 0)) - $F13 + $B13) | K13: =IF(D13=0, "Even Keel", "")
A14: =IF(December_Tide_2025!A14="","",December_Tide_2025!A14) | B14: =IF(December_Tide_2025!B14="","",December_Tide_2025!B14) | C14: =IF($A14="","", INDEX(Calc!$E:$E, MATCH("KminusZ_m", Calc!$C:$C, 0)) + $B14 - INDEX(Calc!$E:$E, MATCH("L_ramp_m", Calc!$C:$C, 0)) * TAN(RADIANS(INDEX(Calc!$E:$E, MATCH("theta_max_deg", Calc!$C:$C, 0))))) | E14: =IF($C14="","", IF($D14="", $C14, $C14 - $D14/2)) | F14: =IF($C14="","", IF($D14="", $C14, $C14 + $D14/2)) | G14: =IF($E14="","", DEGREES(ATAN((INDEX(Calc!$E:$E, MATCH("KminusZ_m", Calc!$C:$C, 0)) - $E14 + $B14) / INDEX(Calc!$E:$E, MATCH("L_ramp_m", Calc!$C:$C, 0))))) | H14: =IF($E14="","", IF(AND($E14>=INDEX(Calc!$E:$E, MATCH("min_fwd_draft_m", Calc!$C:$C, 0)), $E14<=INDEX(Calc!$E:$E, MATCH("max_fwd_draft_m", Calc!$C:$C, 0)), $G14<=INDEX(Calc!$E:$E, MATCH("theta_max_deg", Calc!$C:$C, 0))), "OK", "CHECK")) | I14: =IF($E14="","", INDEX(Calc!$E:$E, MATCH("D_vessel_m", Calc!$C:$C, 0)) - $E14 + $B14) | J14: =IF($F14="","", INDEX(Calc!$E:$E, MATCH("D_vessel_m", Calc!$C:$C, 0)) - $F14 + $B14) | K14: =IF(D14=0, "Even Keel", "")
... A745: =IF(December_Tide_2025!A745="","",December_Tide_2025!A745) | B745: =IF(December_Tide_2025!B745="","",December_Tide_2025!B745) | C745: =IF($A745="","", INDEX(Calc!$E:$E, MATCH("KminusZ_m", Calc!$C:$C, 0)) + $B745 - INDEX(Calc!$E:$E, MATCH("L_ramp_m", Calc!$C:$C, 0)) * TAN(RADIANS(INDEX(Calc!$E:$E, MATCH("theta_max_deg", Calc!$C:$C, 0))))) | E745: =IF($C745="","", IF($D745="", $C745, $C745 - $D745/2)) | F745: =IF($C745="","", IF($D745="", $C745, $C745 + $D745/2)) | G745: =IF($E745="","", DEGREES(ATAN((INDEX(Calc!$E:$E, MATCH("KminusZ_m", Calc!$C:$C, 0)) - $E745 + $B745) / INDEX(Calc!$E:$E, MATCH("L_ramp_m", Calc!$C:$C, 0))))) | H745: =IF($E745="","", IF(AND($E745>=INDEX(Calc!$E:$E, MATCH("min_fwd_draft_m", Calc!$C:$C, 0)), $E745<=INDEX(Calc!$E:$E, MATCH("max_fwd_draft_m", Calc!$C:$C, 0)), $G745<=INDEX(Calc!$E:$E, MATCH("theta_max_deg", Calc!$C:$C, 0))), "OK", "CHECK")) | I745: =IF($E745="","", INDEX(Calc!$E:$E, MATCH("D_vessel_m", Calc!$C:$C, 0)) - $E745 + $B745) | J745: =IF($F745="","", INDEX(Calc!$E:$E, MATCH("D_vessel_m", Calc!$C:$C, 0)) - $F745 + $B745) | K745: =IF(D745=0, "Even Keel", "")

Sheet RORO_Stage_Scenarios
A1: RORO Stage Scenarios – Option C (Target 240cm Safe Margin)
C2: ← Input parameter(yellow cellls only)
A4: 1.Critical Stage Verification: Trim & Draft Status Sequence | F4: 2. Stage Sequence Table
A5: Parameter | B5: Value | C5: Unit | D5: REMARK | F5: Stage | G5: EXPLANATION | O5: Fwd Draft (m) | P5: Freeboard (m) | Q5: Aft Draft (m) | R5: Status Assessment
A6: Tmean_baseline | B6: 3.2681467 | C6: m | D6: Baseline mean draft (from hydro table) | F6: Stage 1 | G6: Arrival lightship condition. Baseline drafts, trim, and GM are checked before any cargo loading or ballast change.
A7: Forecast_Tide_m | B7: 2 | C7: m | D7: Forecast tide level (CD). NOT Required_WL_m. | F7: Stage 2 | G7: TR1 roll-on start – first axle on the ramp. Initial bow-down trim response is checked against allowable draft and freeboard limits.
A8: Trim_target_cm | B8: 10 | C8: cm | D8: Target trim | F8: Stage 3 | G8: TR1 mid-ramp – transformer COG on the ramp. Progressive bow-down trim is monitored to remain within the allowable envelope.
A9: MTC | B9: =INDEX(Calc!$E:$E, MATCH("MTC_t_m_per_cm", Calc!$C:$C, 0)) | C9: t·m/cm | D9: Moment to change trim | F9: Stage 4 | G9: TR1 fully on deck. Weight is completely transferred from ramp to vessel deck; deck loading, ramp condition, drafts, and trim are verified.
A10: LCF | B10: =Calc!$E$15 | C10: m | D10: Longitudinal center of flotation (from midship, for TM calculation) | F10: Stage 5 | G10: TR1 secured at final aft stowage position (around Fr.42). New reference condition with TR1 only on board, used as the basis for D-1 stern pre-ballasting using FW2 (Fr.0–6, aft).
A11: D_vessel | B11: 3.65 | C11: m | D11: Vessel depth | F11: Stage 5_PreBallast | G11: Pre-ballast condition with TR1 only on board (D-1, using shore water). An intentional stern trim is set using the aft FW2 fresh water tanks (Fr.0–6, AFT, Ballast CG near FR 3.0) so that the bow-down trimming moment of TR2 at ramp entry is counterbalanced and the forward draft remains within the 2.70 m AGI limit without any major dynamic ballasting during the critical RORO operation on D-day.
A12: TPC | B12: =INDEX(Calc!$E:$E, MATCH("TPC_t_per_cm", Calc!$C:$C, 0)) | C12: t/cm | D12: Tons per centimeter | F12: Stage 6A_Critical (Opt C) | G12: Critical TR2 ramp-entry condition on D-day with the D-1 stern pre-ballast (FW2, Fr.0–6) kept fixed. This stage is used to check worst-case forward draft against the 2.70 m limit, trim envelope, GM criteria, and ramp/linkspan clearance under combined TR1+TR2 loading.
A13: pump_rate_effective_tph | B13: =INDEX(Calc!$E:$E, MATCH("pump_rate_effective_tph", Calc!$C:$C, 0)) | C13: t/h | D13: Effective pump rate | F13: Stage 6C_TotalMassOpt | G13: Alternative "total mass optimized" final condition with TR1 and TR2 on deck and higher combined cargo+ballast weight. Sensitivity case to assess maximum displacement effects on drafts, trim, GM and freeboard.
A14: X_Ballast | B14: 0.119 | C14: m | D14: Ballast center position (from AP, Stern FW2) | F14: Stage 6C | G14: Planned final stowage condition with TR1 and TR2 secured on deck and ballast as per departure plan. Main departure case for checking GM, trim and freeboard criteria.
A15: Lpp | B15: 60.302 | C15: m | D15: Length between perpendiculars | F15: Stage 7 | G15: Post-operation lightship/reference condition after cargo is discharged. Used to reconfirm hydrostatic characteristics and GM consistency against Stage 1.
A17: 4. Ballast Water Optimization Matrix & Safety Margins (Auto Pre-ballast)
A18: Stage | B18: W_stage_t | C18: Fr_stage | D18: x_stage_m | E18: TM (t·m) | F18: Trim_cm | G18: FWD_precise_m | H18: AFT_precise_m | I18: ΔTM_cm_tm | J18: Lever_arm_m | K18: Ballast_t_calc | L18: Ballast_time_h_calc | M18: Ballast_t | N18: Ballast_time_h | O18: Trim_Check | P18: Dfwd_m | Q18: Daft_m | R18: Trim_target_stage_cm | S18: FWD_DeckElev_CD_m | T18: AFT_DeckElev_CD_m | U18: GM(m) | V18: Fwd Draft(m) | W18: vs 2.70m | X18: De-ballast Qty(t) | Y18: Timing | Z18: Phys_Freeboard_m | AA18: Clearance_Check | AB18: GM_calc | AC18: GM_Check | AD18: Disp_total_t | AE18: Vent_Time_h | AF18: Trim_gate_cm | AG18: Gate_Ballast_net_t | AH18: Dfwd_gate_m | AI18: Gate_iter_n | AJ18: Gate_Flag | AK18: Share_Load_t | AL18: Share_Check | AM18: Hinge_Rx_t | AN18: Rx_Check | AO18: Deck_Press_t/m² | AP18: Press_Check | AQ18: Load_Case_B_t | AR18: Heel_deg | AS18: GM_eff_m | AT18: Ballast_req_t | AU18: Ballast_gap_t | AV18: Time_Add_h | AW18: Ramp_Angle_deg | AX18: Ramp_Angle_Check | AY18: Pin_Stress_N/mm² | AZ18: Von_Mises_Check | BA18: Required_WL_m | BB18: WL_OK | BC18: Draft_FWD_m_solver | BD18: Draft_AFT_m_solver | BE18: Draft_Source | BF18: Gate_AFT_MIN_2p70_PASS | BG18: AFT_Margin_2p70_m | BH18: Gate_B_Applies | BI18: Gate_FWD_MAX_2p70_critical_only | BJ18: FWD_Margin_2p70_m | BK18: Gate_Freeboard_ND | BL18: Freeboard_Req_ND_m | BM18: Freeboard_ND_Margin_m | BN18: D_vessel_m | BO18: Draft_Max_raw_m | BP18: Draft_Max_solver_m | BQ18: Draft_Clipped_raw | BR18: Draft_Clipped_solver
A19: Stage 1 | B19: 2800 | D19: 0 | E19: 0 | F19: 0 | G19: 3.2681467 | H19: 3.2681467 | I19: =IF($A19="","",(IF($R19="",$B$8,$R19) - F19) * $B$9) | J19: =IF(OR(ISBLANK($B$14), ISBLANK($B$10), ISBLANK($B$15), ISERROR($B$10)), "", ROUND($B$14 - ($B$10 + $B$15/2), 2)) | K19: =IF(OR($A19="",$J19="", $J19=0),"",ROUND(I19 / $J19, 2)) | L19: =IF(OR(K19="", $B$13="", $B$13=0, ISERROR($B$13)), "", ROUND(ABS(K19) / $B$13, 2)) | M19: =IF(OR(F19="", OR($B$12="", $B$12=0)), "", ROUND(ABS(F19/100) * 50 * $B$12, 2)) | N19: =IF(OR(L19="", $B$13="", $B$13=0, ISERROR($B$13)), "", ROUND(L19 / $B$13, 2)) | O19: =IF(F19="", "", IF(ABS(F19/100) <= ($B$15/50), "OK", "EXCESSIVE")) | P19: =IF($A19="","",G19) | Q19: =IF($A19="","",H19) | R19: 113.62934 | S19: =IF(P19="", "", $B$11 - P19 + $B$7) | T19: =IF(Q19="", "", $B$11 - Q19 + $B$7) | U19: 7.93 | V19: =P19 | W19: =IF(V19="","",IF(V19<=Calc!$E$18,"OK","NG")) | X19: =K19 | Z19: =IFERROR(IF(P19="","",$B$11 - P19 - Calc!$E$19), "") | AA19: =IFERROR(IF(Z19="", "", IF(Z19>=Calc!$E$20, "OK", "<0.28m CHECK")), "") | AB19: 7.93 | AC19: OK | AD19: =IF(A19="","",CONST_TANKS!$C$13+L19+B19) | AE19: =IFERROR(IF(OR(X19="",$B$13="",$B$13=0),"",ROUND(ABS(X19)/$B$13,2)),"") | AF19: 113.62934 | AG19: 1014.28 | AH19: 3.480066 | AI19: 0 | AJ19: LIMIT | AL19: =IF(AK19="", "", IF(AK19<=Calc!$E$24, "OK", "CHECK")) | AM19: =IF(AK19="", 45, 45 + AK19 * 0.545) | AN19: =IF(AM19="", "", IF(AM19<=Calc!$E$37, "OK", "NG")) | AO19: =IF(AK19="", "", AK19/Calc!$E$26) | AP19: =IF(AO19="", "", IF(AO19<=Calc!$E$25, "OK", "CHECK")) | AQ19: =IF(AK19="", "", AK19 * Calc!$E$42) | AR19: =IFERROR(IF(OR($A19="",U19="",AD19="",AD19=0),"",DEGREES((B19*Calc!$E$43)/(AD19*U19))),"") | AS19: =IFERROR(IF(OR($A19="", U19="", AD19="", AD19=0), "", U19 - CONST_TANKS!$E$13 / AD19),"") | AT19: =IF($A19="","",IF(OR($I19="",$I19=0),0,ROUND(H19/$I19,2))) | AU19: =IF($A19="","",AT19 - $L19) | AV19: =IF($A19="","",IF($B$13=0,0,AU19/$B$13)) | AW19: =IF(Z19="","",DEGREES(ASIN((Z19-Calc!$E$35)/Calc!$E$33))) | AX19: =IF(AW19="","",IF(AW19<=6,"OK","NG")) | AY19: =IF(AM19="","",(AM19/4)/Calc!$E$36*9.81/1000) | AZ19: =IF(AY19="","",IF(AY19<=188,"OK","NG")) | BA19: =IF(Z19="", "", IF(Z19>=0, 0, ABS(Z19)+0.30)) | BB19: =IF(BA19="", "", IF($B$7>=BA19, "OK", "CHECK")) | BE19: solver | BN19: 3.65
A20: Stage 2 | B20: 3071.2 | C20: 26.15 | D20: 4 | E20: 878.4168 | F20: 20.599402 | G20: 3.4239841 | H20: 3.6299781 | I20: =IF($A20="","",(IF($R20="",$B$8,$R20) - F20) * $B$9) | J20: =IF(OR(ISBLANK($B$14), ISBLANK($B$10), ISBLANK($B$15), ISERROR($B$10)), "", ROUND($B$14 - ($B$10 + $B$15/2), 2)) | K20: =IF(OR($A20="",$J20="", $J20=0),"",ROUND(I20 / $J20, 2)) | L20: =IF(OR(K20="", $B$13="", $B$13=0, ISERROR($B$13)), "", ROUND(ABS(K20) / $B$13, 2)) | M20: =IF(OR(F20="", OR($B$12="", $B$12=0)), "", ROUND(ABS(F20/100) * 50 * $B$12, 2)) | N20: =IF(OR(L20="", $B$13="", $B$13=0, ISERROR($B$13)), "", ROUND(L20 / $B$13, 2)) | O20: =IF(F20="", "", IF(ABS(F20/100) <= ($B$15/50), "OK", "EXCESSIVE")) | P20: =IF($A20="","",G20) | Q20: =IF($A20="","",H20) | R20: 165.39623 | S20: =IF(P20="", "", $B$11 - P20 + $B$7) | T20: =IF(Q20="", "", $B$11 - Q20 + $B$7) | U20: 7.29 | V20: =P20 | W20: =IF(V20="","",IF(V20<=Calc!$E$18,"OK","NG")) | X20: =K20 | Z20: =IFERROR(IF(P20="","",$B$11 - P20 - Calc!$E$19), "") | AA20: =IFERROR(IF(Z20="", "", IF(Z20>=Calc!$E$20, "OK", "<0.28m CHECK")), "") | AB20: 7.29 | AC20: OK | AD20: =IF(A20="","",CONST_TANKS!$C$13+L20+B20) | AE20: =IFERROR(IF(OR(X20="",$B$13="",$B$13=0),"",ROUND(ABS(X20)/$B$13,2)),"") | AF20: 165.39623 | AG20: 1292.49 | AH20: 3.269401 | AI20: 0 | AJ20: LIMIT | AL20: =IF(AK20="", "", IF(AK20<=Calc!$E$24, "OK", "CHECK")) | AM20: =IF(AK20="", 45, 45 + AK20 * 0.545) | AN20: =IF(AM20="", "", IF(AM20<=Calc!$E$37, "OK", "NG")) | AO20: =IF(AK20="", "", AK20/Calc!$E$26) | AP20: =IF(AO20="", "", IF(AO20<=Calc!$E$25, "OK", "CHECK")) | AQ20: =IF(AK20="", "", AK20 * Calc!$E$42) | AR20: =IFERROR(IF(OR($A20="",U20="",AD20="",AD20=0),"",DEGREES((B20*Calc!$E$43)/(AD20*U20))),"") | AS20: =IFERROR(IF(OR($A20="", U20="", AD20="", AD20=0), "", U20 - CONST_TANKS!$E$13 / AD20),"") | AT20: =IF($A20="","",IF(OR($I20="",$I20=0),0,ROUND(H20/$I20,2))) | AU20: =IF($A20="","",AT20 - $L20) | AV20: =IF($A20="","",IF($B$13=0,0,AU20/$B$13)) | AW20: =IF(Z20="","",DEGREES(ASIN((Z20-Calc!$E$35)/Calc!$E$33))) | AX20: =IF(AW20="","",IF(AW20<=6,"OK","NG")) | AY20: =IF(AM20="","",(AM20/4)/Calc!$E$36*9.81/1000) | AZ20: =IF(AY20="","",IF(AY20<=188,"OK","NG")) | BA20: =IF(Z20="", "", IF(Z20>=0, 0, ABS(Z20)+0.30)) | BB20: =IF(BA20="", "", IF($B$7>=BA20, "OK", "CHECK")) | BE20: solver | BN20: 3.65
A21: Stage 3 | B21: 3071.2 | C21: 26.15 | D21: 4 | E21: 878.4168 | F21: 20.599402 | G21: 3.4239841 | H21: 3.6299781 | I21: =IF($A21="","",(IF($R21="",$B$8,$R21) - F21) * $B$9) | J21: =IF(OR(ISBLANK($B$14), ISBLANK($B$10), ISBLANK($B$15), ISERROR($B$10)), "", ROUND($B$14 - ($B$10 + $B$15/2), 2)) | K21: =IF(OR($A21="",$J21="", $J21=0),"",ROUND(I21 / $J21, 2)) | L21: =IF(OR(K21="", $B$13="", $B$13=0, ISERROR($B$13)), "", ROUND(ABS(K21) / $B$13, 2)) | M21: =IF(OR(F21="", OR($B$12="", $B$12=0)), "", ROUND(ABS(F21/100) * 50 * $B$12, 2)) | N21: =IF(OR(L21="", $B$13="", $B$13=0, ISERROR($B$13)), "", ROUND(L21 / $B$13, 2)) | O21: =IF(F21="", "", IF(ABS(F21/100) <= ($B$15/50), "OK", "EXCESSIVE")) | P21: =IF($A21="","",G21) | Q21: =IF($A21="","",H21) | R21: 165.39623 | S21: =IF(P21="", "", $B$11 - P21 + $B$7) | T21: =IF(Q21="", "", $B$11 - Q21 + $B$7) | U21: 7.29 | V21: =P21 | W21: =IF(V21="","",IF(V21<=Calc!$E$18,"OK","NG")) | X21: =K21 | Z21: =IFERROR(IF(P21="","",$B$11 - P21 - Calc!$E$19), "") | AA21: =IFERROR(IF(Z21="", "", IF(Z21>=Calc!$E$20, "OK", "<0.28m CHECK")), "") | AB21: 7.29 | AC21: OK | AD21: =IF(A21="","",CONST_TANKS!$C$13+L21+B21) | AE21: =IFERROR(IF(OR(X21="",$B$13="",$B$13=0),"",ROUND(ABS(X21)/$B$13,2)),"") | AF21: 165.39623 | AG21: 1292.49 | AH21: 3.269401 | AI21: 0 | AJ21: LIMIT | AL21: =IF(AK21="", "", IF(AK21<=Calc!$E$24, "OK", "CHECK")) | AM21: =IF(AK21="", 45, 45 + AK21 * 0.545) | AN21: =IF(AM21="", "", IF(AM21<=Calc!$E$37, "OK", "NG")) | AO21: =IF(AK21="", "", AK21/Calc!$E$26) | AP21: =IF(AO21="", "", IF(AO21<=Calc!$E$25, "OK", "CHECK")) | AQ21: =IF(AK21="", "", AK21 * Calc!$E$42) | AR21: =IFERROR(IF(OR($A21="",U21="",AD21="",AD21=0),"",DEGREES((B21*Calc!$E$43)/(AD21*U21))),"") | AS21: =IFERROR(IF(OR($A21="", U21="", AD21="", AD21=0), "", U21 - CONST_TANKS!$E$13 / AD21),"") | AT21: =IF($A21="","",IF(OR($I21="",$I21=0),0,ROUND(H21/$I21,2))) | AU21: =IF($A21="","",AT21 - $L21) | AV21: =IF($A21="","",IF($B$13=0,0,AU21/$B$13)) | AW21: =IF(Z21="","",DEGREES(ASIN((Z21-Calc!$E$35)/Calc!$E$33))) | AX21: =IF(AW21="","",IF(AW21<=6,"OK","NG")) | AY21: =IF(AM21="","",(AM21/4)/Calc!$E$36*9.81/1000) | AZ21: =IF(AY21="","",IF(AY21<=188,"OK","NG")) | BA21: =IF(Z21="", "", IF(Z21>=0, 0, ABS(Z21)+0.30)) | BB21: =IF(BA21="", "", IF($B$7>=BA21, "OK", "CHECK")) | BE21: solver | BN21: 3.65
A22: Stage 4 | B22: 3071.2 | C22: 25.65 | D22: 4.5 | E22: 1014.0168 | F22: 23.779303 | G22: 3.4080846 | H22: 3.6458776 | I22: =IF($A22="","",(IF($R22="",$B$8,$R22) - F22) * $B$9) | J22: =IF(OR(ISBLANK($B$14), ISBLANK($B$10), ISBLANK($B$15), ISERROR($B$10)), "", ROUND($B$14 - ($B$10 + $B$15/2), 2)) | K22: =IF(OR($A22="",$J22="", $J22=0),"",ROUND(I22 / $J22, 2)) | L22: =IF(OR(K22="", $B$13="", $B$13=0, ISERROR($B$13)), "", ROUND(ABS(K22) / $B$13, 2)) | M22: =IF(OR(F22="", OR($B$12="", $B$12=0)), "", ROUND(ABS(F22/100) * 50 * $B$12, 2)) | N22: =IF(OR(L22="", $B$13="", $B$13=0, ISERROR($B$13)), "", ROUND(L22 / $B$13, 2)) | O22: =IF(F22="", "", IF(ABS(F22/100) <= ($B$15/50), "OK", "EXCESSIVE")) | P22: =IF($A22="","",G22) | Q22: =IF($A22="","",H22) | R22: 165.39623 | S22: =IF(P22="", "", $B$11 - P22 + $B$7) | T22: =IF(Q22="", "", $B$11 - Q22 + $B$7) | U22: 7.29 | V22: =P22 | W22: =IF(V22="","",IF(V22<=Calc!$E$18,"OK","NG")) | X22: =K22 | Z22: =IFERROR(IF(P22="","",$B$11 - P22 - Calc!$E$19), "") | AA22: =IFERROR(IF(Z22="", "", IF(Z22>=Calc!$E$20, "OK", "<0.28m CHECK")), "") | AB22: 7.29 | AC22: OK | AD22: =IF(A22="","",CONST_TANKS!$C$13+L22+B22) | AE22: =IFERROR(IF(OR(X22="",$B$13="",$B$13=0),"",ROUND(ABS(X22)/$B$13,2)),"") | AF22: 165.39623 | AG22: 1264.1 | AH22: 3.2664159 | AI22: 0 | AJ22: LIMIT | AL22: =IF(AK22="", "", IF(AK22<=Calc!$E$24, "OK", "CHECK")) | AM22: =IF(AK22="", 45, 45 + AK22 * 0.545) | AN22: =IF(AM22="", "", IF(AM22<=Calc!$E$37, "OK", "NG")) | AO22: =IF(AK22="", "", AK22/Calc!$E$26) | AP22: =IF(AO22="", "", IF(AO22<=Calc!$E$25, "OK", "CHECK")) | AQ22: =IF(AK22="", "", AK22 * Calc!$E$42) | AR22: =IFERROR(IF(OR($A22="",U22="",AD22="",AD22=0),"",DEGREES((B22*Calc!$E$43)/(AD22*U22))),"") | AS22: =IFERROR(IF(OR($A22="", U22="", AD22="", AD22=0), "", U22 - CONST_TANKS!$E$13 / AD22),"") | AT22: =IF($A22="","",IF(OR($I22="",$I22=0),0,ROUND(H22/$I22,2))) | AU22: =IF($A22="","",AT22 - $L22) | AV22: =IF($A22="","",IF($B$13=0,0,AU22/$B$13)) | AW22: =IF(Z22="","",DEGREES(ASIN((Z22-Calc!$E$35)/Calc!$E$33))) | AX22: =IF(AW22="","",IF(AW22<=6,"OK","NG")) | AY22: =IF(AM22="","",(AM22/4)/Calc!$E$36*9.81/1000) | AZ22: =IF(AY22="","",IF(AY22<=188,"OK","NG")) | BA22: =IF(Z22="", "", IF(Z22>=0, 0, ABS(Z22)+0.30)) | BB22: =IF(BA22="", "", IF($B$7>=BA22, "OK", "CHECK")) | BE22: solver | BN22: 3.65
A23: Stage 5 | B23: 3071.2 | C23: 25.65 | D23: 4.5 | E23: 1014.0168 | F23: 23.779303 | G23: 3.4080846 | H23: 3.6458776 | I23: =IF($A23="","",(IF($R23="",$B$8,$R23) - F23) * $B$9) | J23: =IF(OR(ISBLANK($B$14), ISBLANK($B$10), ISBLANK($B$15), ISERROR($B$10)), "", ROUND($B$14 - ($B$10 + $B$15/2), 2)) | K23: =IF(OR($A23="",$J23="", $J23=0),"",ROUND(I23 / $J23, 2)) | L23: =IF(OR(K23="", $B$13="", $B$13=0, ISERROR($B$13)), "", ROUND(ABS(K23) / $B$13, 2)) | M23: =IF(OR(F23="", OR($B$12="", $B$12=0)), "", ROUND(ABS(F23/100) * 50 * $B$12, 2)) | N23: =IF(OR(L23="", $B$13="", $B$13=0, ISERROR($B$13)), "", ROUND(L23 / $B$13, 2)) | O23: =IF(F23="", "", IF(ABS(F23/100) <= ($B$15/50), "OK", "EXCESSIVE")) | P23: =IF($A23="","",G23) | Q23: =IF($A23="","",H23) | R23: 165.39623 | S23: =IF(P23="", "", $B$11 - P23 + $B$7) | T23: =IF(Q23="", "", $B$11 - Q23 + $B$7) | U23: 7.29 | V23: =P23 | W23: =IF(V23="","",IF(V23<=Calc!$E$18,"OK","NG")) | X23: =K23 | Z23: =IFERROR(IF(P23="","",$B$11 - P23 - Calc!$E$19), "") | AA23: =IFERROR(IF(Z23="", "", IF(Z23>=Calc!$E$20, "OK", "<0.28m CHECK")), "") | AB23: 7.29 | AC23: OK | AD23: =IF(A23="","",CONST_TANKS!$C$13+L23+B23) | AE23: =IFERROR(IF(OR(X23="",$B$13="",$B$13=0),"",ROUND(ABS(X23)/$B$13,2)),"") | AF23: 165.39623 | AG23: 1264.1 | AH23: 3.2664159 | AI23: 0 | AJ23: LIMIT | AL23: =IF(AK23="", "", IF(AK23<=Calc!$E$24, "OK", "CHECK")) | AM23: =IF(AK23="", 45, 45 + AK23 * 0.545) | AN23: =IF(AM23="", "", IF(AM23<=Calc!$E$37, "OK", "NG")) | AO23: =IF(AK23="", "", AK23/Calc!$E$26) | AP23: =IF(AO23="", "", IF(AO23<=Calc!$E$25, "OK", "CHECK")) | AQ23: =IF(AK23="", "", AK23 * Calc!$E$42) | AR23: =IFERROR(IF(OR($A23="",U23="",AD23="",AD23=0),"",DEGREES((B23*Calc!$E$43)/(AD23*U23))),"") | AS23: =IFERROR(IF(OR($A23="", U23="", AD23="", AD23=0), "", U23 - CONST_TANKS!$E$13 / AD23),"") | AT23: =IF($A23="","",IF(OR($I23="",$I23=0),0,ROUND(H23/$I23,2))) | AU23: =IF($A23="","",AT23 - $L23) | AV23: =IF($A23="","",IF($B$13=0,0,AU23/$B$13)) | AW23: =IF(Z23="","",DEGREES(ASIN((Z23-Calc!$E$35)/Calc!$E$33))) | AX23: =IF(AW23="","",IF(AW23<=6,"OK","NG")) | AY23: =IF(AM23="","",(AM23/4)/Calc!$E$36*9.81/1000) | AZ23: =IF(AY23="","",IF(AY23<=188,"OK","NG")) | BA23: =IF(Z23="", "", IF(Z23>=0, 0, ABS(Z23)+0.30)) | BB23: =IF(BA23="", "", IF($B$7>=BA23, "OK", "CHECK")) | BE23: solver | BN23: 3.65
A24: Stage 5_PreBallast | B24: 3217.2736 | C24: 25.65 | D24: 4.51 | E24: 1128.2868 | F24: 33.184906 | G24: 1.8340755 | H24: 2.1659245 | I24: =IF($A24="","",(IF($R24="",$B$8,$R24) - F24) * $B$9) | J24: =IF(OR(ISBLANK($B$14), ISBLANK($B$10), ISBLANK($B$15), ISERROR($B$10)), "", ROUND($B$14 - ($B$10 + $B$15/2), 2)) | K24: =IF(OR($A24="",$J24="", $J24=0),"",ROUND(I24 / $J24, 2)) | L24: =IF(OR(K24="", $B$13="", $B$13=0, ISERROR($B$13)), "", ROUND(ABS(K24) / $B$13, 2)) | M24: =IF(OR(F24="", OR($B$12="", $B$12=0)), "", ROUND(ABS(F24/100) * 50 * $B$12, 2)) | N24: =IF(OR(L24="", $B$13="", $B$13=0, ISERROR($B$13)), "", ROUND(L24 / $B$13, 2)) | O24: =IF(F24="", "", IF(ABS(F24/100) <= ($B$15/50), "OK", "EXCESSIVE")) | P24: =IF($A24="","",G24) | Q24: =IF($A24="","",H24) | R24: 192.87228 | S24: =IF(P24="", "", $B$11 - P24 + $B$7) | T24: =IF(Q24="", "", $B$11 - Q24 + $B$7) | U24: 8.45 | V24: =P24 | W24: =IF(V24="","",IF(V24<=Calc!$E$18,"OK","NG")) | X24: =K24 | Z24: =IFERROR(IF(P24="","",$B$11 - P24 - Calc!$E$19), "") | AA24: =IFERROR(IF(Z24="", "", IF(Z24>=Calc!$E$20, "OK", "<0.28m CHECK")), "") | AB24: 8.45 | AC24: OK | AD24: =IF(A24="","",CONST_TANKS!$C$13+L24+B24) | AE24: =IFERROR(IF(OR(X24="",$B$13="",$B$13=0),"",ROUND(ABS(X24)/$B$13,2)),"") | AF24: 192.87228 | AG24: -370 | AH24: 3.2713289 | AI24: 3 | AJ24: LIMIT | AL24: =IF(AK24="", "", IF(AK24<=Calc!$E$24, "OK", "CHECK")) | AM24: =IF(AK24="", 45, 45 + AK24 * 0.545) | AN24: =IF(AM24="", "", IF(AM24<=Calc!$E$37, "OK", "NG")) | AO24: =IF(AK24="", "", AK24/Calc!$E$26) | AP24: =IF(AO24="", "", IF(AO24<=Calc!$E$25, "OK", "CHECK")) | AQ24: =IF(AK24="", "", AK24 * Calc!$E$42) | AR24: =IFERROR(IF(OR($A24="",U24="",AD24="",AD24=0),"",DEGREES((B24*Calc!$E$43)/(AD24*U24))),"") | AS24: =IFERROR(IF(OR($A24="", U24="", AD24="", AD24=0), "", U24 - CONST_TANKS!$E$13 / AD24),"") | AT24: =IF($A24="","",IF(OR($I24="",$I24=0),0,ROUND(H24/$I24,2))) | AU24: =IF($A24="","",AT24 - $L24) | AV24: =IF($A24="","",IF($B$13=0,0,AU24/$B$13)) | AW24: =IF(Z24="","",DEGREES(ASIN((Z24-Calc!$E$35)/Calc!$E$33))) | AX24: =IF(AW24="","",IF(AW24<=6,"OK","NG")) | AY24: =IF(AM24="","",(AM24/4)/Calc!$E$36*9.81/1000) | AZ24: =IF(AY24="","",IF(AY24<=188,"OK","NG")) | BA24: =IF(Z24="", "", IF(Z24>=0, 0, ABS(Z24)+0.30)) | BB24: =IF(BA24="", "", IF($B$7>=BA24, "OK", "CHECK")) | BE24: solver | BN24: 3.65
A25: Stage 6A_Critical (Opt C) | B25: 3372.4 | C25: 25.36 | D25: 4.79 | E25: 2307.7356 | F25: 67.874576 | G25: 1.6606271 | H25: 2.3393729 | I25: =IF($A25="","",(IF($R25="",$B$8,$R25) - F25) * $B$9) | J25: =IF(OR(ISBLANK($B$14), ISBLANK($B$10), ISBLANK($B$15), ISERROR($B$10)), "", ROUND($B$14 - ($B$10 + $B$15/2), 2)) | K25: =IF(OR($A25="",$J25="", $J25=0),"",ROUND(I25 / $J25, 2)) | L25: =IF(OR(K25="", $B$13="", $B$13=0, ISERROR($B$13)), "", ROUND(ABS(K25) / $B$13, 2)) | M25: =IF(OR(F25="", OR($B$12="", $B$12=0)), "", ROUND(ABS(F25/100) * 50 * $B$12, 2)) | N25: =IF(OR(L25="", $B$13="", $B$13=0, ISERROR($B$13)), "", ROUND(L25 / $B$13, 2)) | O25: =IF(F25="", "", IF(ABS(F25/100) <= ($B$15/50), "OK", "EXCESSIVE")) | P25: =IF($A25="","",G25) | Q25: =IF($A25="","",H25) | R25: 221.94393 | S25: =IF(P25="", "", $B$11 - P25 + $B$7) | T25: =IF(Q25="", "", $B$11 - Q25 + $B$7) | U25: 8.45 | V25: =P25 | W25: =IF(V25="","",IF(V25<=Calc!$E$18,"OK","NG")) | X25: =K25 | Z25: =IFERROR(IF(P25="","",$B$11 - P25 - Calc!$E$19), "") | AA25: =IFERROR(IF(Z25="", "", IF(Z25>=Calc!$E$20, "OK", "<0.28m CHECK")), "") | AB25: 8.45 | AC25: OK | AD25: =IF(A25="","",CONST_TANKS!$C$13+L25+B25) | AE25: =IFERROR(IF(OR(X25="",$B$13="",$B$13=0),"",ROUND(ABS(X25)/$B$13,2)),"") | AF25: 221.94393 | AG25: -370 | AH25: 3.3395574 | AI25: 3 | AJ25: LIMIT | AL25: =IF(AK25="", "", IF(AK25<=Calc!$E$24, "OK", "CHECK")) | AM25: =IF(AK25="", 45, 45 + AK25 * 0.545) | AN25: =IF(AM25="", "", IF(AM25<=Calc!$E$37, "OK", "NG")) | AO25: =IF(AK25="", "", AK25/Calc!$E$26) | AP25: =IF(AO25="", "", IF(AO25<=Calc!$E$25, "OK", "CHECK")) | AQ25: =IF(AK25="", "", AK25 * Calc!$E$42) | AR25: =IFERROR(IF(OR($A25="",U25="",AD25="",AD25=0),"",DEGREES((B25*Calc!$E$43)/(AD25*U25))),"") | AS25: =IFERROR(IF(OR($A25="", U25="", AD25="", AD25=0), "", U25 - CONST_TANKS!$E$13 / AD25),"") | AT25: =IF($A25="","",IF(OR($I25="",$I25=0),0,ROUND(H25/$I25,2))) | AU25: =IF($A25="","",AT25 - $L25) | AV25: =IF($A25="","",IF($B$13=0,0,AU25/$B$13)) | AW25: =IF(Z25="","",DEGREES(ASIN((Z25-Calc!$E$35)/Calc!$E$33))) | AX25: =IF(AW25="","",IF(AW25<=6,"OK","NG")) | AY25: =IF(AM25="","",(AM25/4)/Calc!$E$36*9.81/1000) | AZ25: =IF(AY25="","",IF(AY25<=188,"OK","NG")) | BA25: =IF(Z25="", "", IF(Z25>=0, 0, ABS(Z25)+0.30)) | BB25: =IF(BA25="", "", IF($B$7>=BA25, "OK", "CHECK")) | BE25: solver | BN25: 3.65
A26: Stage 6C_TotalMassOpt | B26: 3372.4 | C26: 27.42 | D26: 2.73 | E26: 1128.0156 | F26: 24.963014 | G26: 3.6849046 | H26: 3.9345347 | I26: =IF($A26="","",(IF($R26="",$B$8,$R26) - F26) * $B$9) | J26: =IF(OR(ISBLANK($B$14), ISBLANK($B$10), ISBLANK($B$15), ISERROR($B$10)), "", ROUND($B$14 - ($B$10 + $B$15/2), 2)) | K26: =IF(OR($A26="",$J26="", $J26=0),"",ROUND(I26 / $J26, 2)) | L26: =IF(OR(K26="", $B$13="", $B$13=0, ISERROR($B$13)), "", ROUND(ABS(K26) / $B$13, 2)) | M26: =IF(OR(F26="", OR($B$12="", $B$12=0)), "", ROUND(ABS(F26/100) * 50 * $B$12, 2)) | N26: =IF(OR(L26="", $B$13="", $B$13=0, ISERROR($B$13)), "", ROUND(L26 / $B$13, 2)) | O26: =IF(F26="", "", IF(ABS(F26/100) <= ($B$15/50), "OK", "EXCESSIVE")) | P26: =IF($A26="","",G26) | Q26: =IF($A26="","",H26) | R26: 221.94393 | S26: =IF(P26="", "", $B$11 - P26 + $B$7) | T26: =IF(Q26="", "", $B$11 - Q26 + $B$7) | U26: 6.76 | V26: =P26 | W26: =IF(V26="","",IF(V26<=Calc!$E$18,"OK","NG")) | X26: =K26 | Z26: =IFERROR(IF(P26="","",$B$11 - P26 - Calc!$E$19), "") | AA26: =IFERROR(IF(Z26="", "", IF(Z26>=Calc!$E$20, "OK", "<0.28m CHECK")), "") | AB26: 6.76 | AC26: OK | AD26: =IF(A26="","",CONST_TANKS!$C$13+L26+B26) | AE26: =IFERROR(IF(OR(X26="",$B$13="",$B$13=0),"",ROUND(ABS(X26)/$B$13,2)),"") | AF26: 221.94393 | AG26: -370 | AH26: 3.480451 | AI26: 3 | AJ26: LIMIT | AL26: =IF(AK26="", "", IF(AK26<=Calc!$E$24, "OK", "CHECK")) | AM26: =IF(AK26="", 45, 45 + AK26 * 0.545) | AN26: =IF(AM26="", "", IF(AM26<=Calc!$E$37, "OK", "NG")) | AO26: =IF(AK26="", "", AK26/Calc!$E$26) | AP26: =IF(AO26="", "", IF(AO26<=Calc!$E$25, "OK", "CHECK")) | AQ26: =IF(AK26="", "", AK26 * Calc!$E$42) | AR26: =IFERROR(IF(OR($A26="",U26="",AD26="",AD26=0),"",DEGREES((B26*Calc!$E$43)/(AD26*U26))),"") | AS26: =IFERROR(IF(OR($A26="", U26="", AD26="", AD26=0), "", U26 - CONST_TANKS!$E$13 / AD26),"") | AT26: =IF($A26="","",IF(OR($I26="",$I26=0),0,ROUND(H26/$I26,2))) | AU26: =IF($A26="","",AT26 - $L26) | AV26: =IF($A26="","",IF($B$13=0,0,AU26/$B$13)) | AW26: =IF(Z26="","",DEGREES(ASIN((Z26-Calc!$E$35)/Calc!$E$33))) | AX26: =IF(AW26="","",IF(AW26<=6,"OK","NG")) | AY26: =IF(AM26="","",(AM26/4)/Calc!$E$36*9.81/1000) | AZ26: =IF(AY26="","",IF(AY26<=188,"OK","NG")) | BA26: =IF(Z26="", "", IF(Z26>=0, 0, ABS(Z26)+0.30)) | BB26: =IF(BA26="", "", IF($B$7>=BA26, "OK", "CHECK")) | BE26: solver | BN26: 3.65
A27: Stage 6C | B27: 3372.4 | C27: 27.42 | D27: 2.73 | E27: 1128.0156 | F27: 24.963014 | G27: 3.6849046 | H27: 3.9345347 | I27: =IF($A27="","",(IF($R27="",$B$8,$R27) - F27) * $B$9) | J27: =IF(OR(ISBLANK($B$14), ISBLANK($B$10), ISBLANK($B$15), ISERROR($B$10)), "", ROUND($B$14 - ($B$10 + $B$15/2), 2)) | K27: =IF(OR($A27="",$J27="", $J27=0),"",ROUND(I27 / $J27, 2)) | L27: =IF(OR(K27="", $B$13="", $B$13=0, ISERROR($B$13)), "", ROUND(ABS(K27) / $B$13, 2)) | M27: =IF(OR(F27="", OR($B$12="", $B$12=0)), "", ROUND(ABS(F27/100) * 50 * $B$12, 2)) | N27: =IF(OR(L27="", $B$13="", $B$13=0, ISERROR($B$13)), "", ROUND(L27 / $B$13, 2)) | O27: =IF(F27="", "", IF(ABS(F27/100) <= ($B$15/50), "OK", "EXCESSIVE")) | P27: =IF($A27="","",G27) | Q27: =IF($A27="","",H27) | R27: 221.94393 | S27: =IF(P27="", "", $B$11 - P27 + $B$7) | T27: =IF(Q27="", "", $B$11 - Q27 + $B$7) | U27: 6.76 | V27: =P27 | W27: =IF(V27="","",IF(V27<=Calc!$E$18,"OK","NG")) | X27: =K27 | Z27: =IFERROR(IF(P27="","",$B$11 - P27 - Calc!$E$19), "") | AA27: =IFERROR(IF(Z27="", "", IF(Z27>=Calc!$E$20, "OK", "<0.28m CHECK")), "") | AB27: 6.76 | AC27: OK | AD27: =IF(A27="","",CONST_TANKS!$C$13+L27+B27) | AE27: =IFERROR(IF(OR(X27="",$B$13="",$B$13=0),"",ROUND(ABS(X27)/$B$13,2)),"") | AF27: 221.94393 | AG27: -370 | AH27: 3.480451 | AI27: 3 | AJ27: LIMIT | AL27: =IF(AK27="", "", IF(AK27<=Calc!$E$24, "OK", "CHECK")) | AM27: =IF(AK27="", 45, 45 + AK27 * 0.545) | AN27: =IF(AM27="", "", IF(AM27<=Calc!$E$37, "OK", "NG")) | AO27: =IF(AK27="", "", AK27/Calc!$E$26) | AP27: =IF(AO27="", "", IF(AO27<=Calc!$E$25, "OK", "CHECK")) | AQ27: =IF(AK27="", "", AK27 * Calc!$E$42) | AR27: =IFERROR(IF(OR($A27="",U27="",AD27="",AD27=0),"",DEGREES((B27*Calc!$E$43)/(AD27*U27))),"") | AS27: =IFERROR(IF(OR($A27="", U27="", AD27="", AD27=0), "", U27 - CONST_TANKS!$E$13 / AD27),"") | AT27: =IF($A27="","",IF(OR($I27="",$I27=0),0,ROUND(H27/$I27,2))) | AU27: =IF($A27="","",AT27 - $L27) | AV27: =IF($A27="","",IF($B$13=0,0,AU27/$B$13)) | AW27: =IF(Z27="","",DEGREES(ASIN((Z27-Calc!$E$35)/Calc!$E$33))) | AX27: =IF(AW27="","",IF(AW27<=6,"OK","NG")) | AY27: =IF(AM27="","",(AM27/4)/Calc!$E$36*9.81/1000) | AZ27: =IF(AY27="","",IF(AY27<=188,"OK","NG")) | BA27: =IF(Z27="", "", IF(Z27>=0, 0, ABS(Z27)+0.30)) | BB27: =IF(BA27="", "", IF($B$7>=BA27, "OK", "CHECK")) | BE27: solver | BN27: 3.65
A28: Stage 7 | B28: 2800 | D28: 0 | E28: 0 | F28: 0 | G28: 3.2681467 | H28: 3.2681467 | I28: =IF($A28="","",(IF($R28="",$B$8,$R28) - F28) * $B$9) | J28: =IF(OR(ISBLANK($B$14), ISBLANK($B$10), ISBLANK($B$15), ISERROR($B$10)), "", ROUND($B$14 - ($B$10 + $B$15/2), 2)) | K28: =IF(OR($A28="",$J28="", $J28=0),"",ROUND(I28 / $J28, 2)) | L28: =IF(OR(K28="", $B$13="", $B$13=0, ISERROR($B$13)), "", ROUND(ABS(K28) / $B$13, 2)) | M28: =IF(OR(F28="", OR($B$12="", $B$12=0)), "", ROUND(ABS(F28/100) * 50 * $B$12, 2)) | N28: =IF(OR(L28="", $B$13="", $B$13=0, ISERROR($B$13)), "", ROUND(L28 / $B$13, 2)) | O28: =IF(F28="", "", IF(ABS(F28/100) <= ($B$15/50), "OK", "EXCESSIVE")) | P28: =IF($A28="","",G28) | Q28: =IF($A28="","",H28) | R28: 113.62934 | S28: =IF(P28="", "", $B$11 - P28 + $B$7) | T28: =IF(Q28="", "", $B$11 - Q28 + $B$7) | U28: 7.93 | V28: =P28 | W28: =IF(V28="","",IF(V28<=Calc!$E$18,"OK","NG")) | X28: =K28 | Z28: =IFERROR(IF(P28="","",$B$11 - P28 - Calc!$E$19), "") | AA28: =IFERROR(IF(Z28="", "", IF(Z28>=Calc!$E$20, "OK", "<0.28m CHECK")), "") | AB28: 7.93 | AC28: OK | AD28: =IF(A28="","",CONST_TANKS!$C$13+L28+B28) | AE28: =IFERROR(IF(OR(X28="",$B$13="",$B$13=0),"",ROUND(ABS(X28)/$B$13,2)),"") | AF28: 113.62934 | AG28: 1014.28 | AH28: 3.480066 | AI28: 0 | AJ28: LIMIT | AL28: =IF(AK28="", "", IF(AK28<=Calc!$E$24, "OK", "CHECK")) | AM28: =IF(AK28="", 45, 45 + AK28 * 0.545) | AN28: =IF(AM28="", "", IF(AM28<=Calc!$E$37, "OK", "NG")) | AO28: =IF(AK28="", "", AK28/Calc!$E$26) | AP28: =IF(AO28="", "", IF(AO28<=Calc!$E$25, "OK", "CHECK")) | AQ28: =IF(AK28="", "", AK28 * Calc!$E$42) | AR28: =IFERROR(IF(OR($A28="",U28="",AD28="",AD28=0),"",DEGREES((B28*Calc!$E$43)/(AD28*U28))),"") | AS28: =IFERROR(IF(OR($A28="", U28="", AD28="", AD28=0), "", U28 - CONST_TANKS!$E$13 / AD28),"") | AT28: =IF($A28="","",IF(OR($I28="",$I28=0),0,ROUND(H28/$I28,2))) | AU28: =IF($A28="","",AT28 - $L28) | AV28: =IF($A28="","",IF($B$13=0,0,AU28/$B$13)) | AW28: =IF(Z28="","",DEGREES(ASIN((Z28-Calc!$E$35)/Calc!$E$33))) | AX28: =IF(AW28="","",IF(AW28<=6,"OK","NG")) | AY28: =IF(AM28="","",(AM28/4)/Calc!$E$36*9.81/1000) | AZ28: =IF(AY28="","",IF(AY28<=188,"OK","NG")) | BA28: =IF(Z28="", "", IF(Z28>=0, 0, ABS(Z28)+0.30)) | BB28: =IF(BA28="", "", IF($B$7>=BA28, "OK", "CHECK")) | BE28: solver | BN28: 3.65

Sheet RORO_Delta_Lever_Report
A1: RORO Stage ΔTM & Lever Arm Verification Report
A3: 주의: ΔTM(Python) vs ΔTM(Excel) 비교. |ΔTM_diff| > 0.50 → Flag=CHECK.
A5: Stage | B5: W_stage_t | C5: x_stage_m | D5: Trim_cm (Python) | E5: Trim_target_stage_cm | F5: MTC_t_m_per_cm | G5: ΔTM_cm_tm (Python) | H5: ΔTM_cm_tm (Excel) | I5: ΔTM_diff (Py-XL) | J5: Flag (|ΔTM_diff|>0.50) | K5: Lever_arm_m (Python) | L5: Ballast_t_calc (Python) | M5: 비고
A6: Stage 1 | B6: 2800 | C6: 0 | D6: 0 | E6: 10 | F6: 0 | G6: 0 | J6: NO_DATA | K6: -30.03 | L6: 0 | M6: MTC=0.0; Excel ΔTM 없음
A7: Stage 2 | B7: 3071.2 | C7: 4 | D7: 20.6 | E7: -96.5 | F7: 0 | G7: 0 | J7: NO_DATA | K7: -30.03 | L7: 0 | M7: MTC=0.0; Excel ΔTM 없음
A8: Stage 3 | B8: 3071.2 | C8: 4 | D8: 20.6 | E8: -96.5 | F8: 0 | G8: 0 | J8: NO_DATA | K8: -30.03 | L8: 0 | M8: MTC=0.0; Excel ΔTM 없음
A9: Stage 4 | B9: 3071.2 | C9: 4.5 | D9: 23.78 | E9: -96.5 | F9: 0 | G9: 0 | J9: NO_DATA | K9: -30.03 | L9: 0 | M9: MTC=0.0; Excel ΔTM 없음
A10: Stage 5 | B10: 3071.2 | C10: 4.5 | D10: 23.78 | E10: -89.58 | F10: 0 | G10: 0 | J10: NO_DATA | K10: -30.03 | L10: 0 | M10: MTC=0.0; Excel ΔTM 없음
A11: Stage 5_PreBallast | B11: 3217.27 | C11: 4.51 | D11: 33.18 | E11: 240 | F11: 0 | G11: 0 | J11: NO_DATA | K11: -30.03 | L11: 0 | M11: MTC=0.0; Excel ΔTM 없음
A12: Stage 6A_Critical (Opt C) | B12: 3372.4 | C12: 4.79 | D12: 67.87 | E12: 10 | F12: 0 | G12: 0 | J12: NO_DATA | K12: -30.03 | L12: 0 | M12: MTC=0.0; Excel ΔTM 없음
A13: Stage 6C_TotalMassOpt | B13: 3372.4 | C13: 2.73 | D13: 24.96 | E13: -96.5 | F13: 0 | G13: 0 | J13: NO_DATA | K13: -30.03 | L13: 0 | M13: MTC=0.0; Excel ΔTM 없음
A14: Stage 6C | B14: 3372.4 | C14: 2.73 | D14: 24.96 | E14: -96.5 | F14: 0 | G14: 0 | J14: NO_DATA | K14: -30.03 | L14: 0 | M14: MTC=0.0; Excel ΔTM 없음
A15: Stage 7 | B15: 2800 | C15: 0 | D15: 0 | E15: 10 | F15: 0 | G15: 0 | J15: NO_DATA | K15: -30.03 | L15: 0 | M15: MTC=0.0; Excel ΔTM 없음

Sheet RORO_Draft_Margin_Check
A1: RORO Stage Draft & Freeboard Margin Check
A3: FWD limit=2.70 m, Linkspan min freeboard=0.28 m 기준.
A5: Stage | B5: Dfwd_m | C5: Daft_m | D5: FWD_margin_m (limit-DFWD) | E5: FWD_Flag | F5: FWD_Freeboard_m (D-Dfwd) | G5: Linkspan_margin_m | H5: Linkspan_Flag | I5: Final_Flag | J5: 비고
A6: Stage 1 | B6: 3.268 | C6: 3.268 | D6: -0.568 | E6: LIMIT | F6: 0.382 | G6: 0.102 | H6: OK | I6: LIMIT
A7: Stage 2 | B7: 3.424 | C7: 3.63 | D7: -0.724 | E7: LIMIT | F7: 0.226 | G7: -0.054 | H7: CONTACT | I7: LIMIT
A8: Stage 3 | B8: 3.424 | C8: 3.63 | D8: -0.724 | E8: LIMIT | F8: 0.226 | G8: -0.054 | H8: CONTACT | I8: LIMIT
A9: Stage 4 | B9: 3.408 | C9: 3.646 | D9: -0.708 | E9: LIMIT | F9: 0.242 | G9: -0.038 | H9: CONTACT | I9: LIMIT
A10: Stage 5 | B10: 3.408 | C10: 3.646 | D10: -0.708 | E10: LIMIT | F10: 0.242 | G10: -0.038 | H10: CONTACT | I10: LIMIT
A11: Stage 5_PreBallast | B11: 1.834 | C11: 2.166 | D11: 0.866 | E11: OK | F11: 1.816 | G11: 1.536 | H11: OK | I11: OK
A12: Stage 6A_Critical (Opt C) | B12: 1.661 | C12: 2.339 | D12: 1.039 | E12: OK | F12: 1.989 | G12: 1.709 | H12: OK | I12: OK
A13: Stage 6C_TotalMassOpt | B13: 3.685 | C13: 3.935 | D13: -0.985 | E13: LIMIT | F13: 0 | G13: -0.28 | H13: CONTACT | I13: LIMIT
A14: Stage 6C | B14: 3.685 | C14: 3.935 | D14: -0.985 | E14: LIMIT | F14: 0 | G14: -0.28 | H14: CONTACT | I14: LIMIT
A15: Stage 7 | B15: 3.268 | C15: 3.268 | D15: -0.568 | E15: LIMIT | F15: 0.382 | G15: 0.102 | H15: OK | I15: LIMIT

Sheet RORO_Stability_Check

Sheet Ballast_Scenario_Comparison
A1: Ballast Scenario Comparison (Option 1 / 2 / 3)
A3: 각 시나리오별 총 Ballast, Pump 시간, FWD Draft margin, Linkspan freeboard margin 비교.
A5: Scenario | B5: Total Ballast_t | C5: Pump Time_h | D5: FWD Draft Margin_m | E5: Linkspan Freeboard Margin_m | F5: Risk Comment
A6: Option 1 – Pre-ballast Only | B6: 1425.41 | C6: 142.54 | D6: 0.87 | E6: 1.54
A7: Option 2 – D-Day Dynamic | B7: 1375.26 | C7: 137.53 | D7: 1.04 | E7: 1.71
A8: Option 3 – Split Stage | B8: 3133.56 | C8: 313.36 | D8: -0.98 | E8: -0.28 | F8: FWD margin < 0.10m; Linkspan margin < 0.10m

Sheet RORO_ISCODE_Check
A1: IS Code (2008) – General Criteria Check (GZ-based)
A3: Stage | B3: Available | C3: PASS | D3: A0-30 (m-rad) | E3: A0-40 (m-rad) | F3: A30-40 (m-rad) | G3: GZmax (m) | H3: Ang@GZmax (deg) | I3: StableRange (deg) | J3: Basis/Missing
A4: Stage 1 | B4: Y | C4: PASS | D4: 0.23561945 | E4: 0.41887902 | F4: 0.18325957 | G4: 1.2 | H4: 40 | I4: 40 | J4: map:data/GZ_Curves.json
A5: Stage 2 | B5: Y | C5: PASS | D5: 0.23561945 | E5: 0.41887902 | F5: 0.18325957 | G5: 1.2 | H5: 40 | I5: 40 | J5: map:data/GZ_Curves.json
A6: Stage 3 | B6: Y | C6: PASS | D6: 0.23561945 | E6: 0.41887902 | F6: 0.18325957 | G6: 1.2 | H6: 40 | I6: 40 | J6: map:data/GZ_Curves.json
A7: Stage 4 | B7: Y | C7: PASS | D7: 0.23561945 | E7: 0.41887902 | F7: 0.18325957 | G7: 1.2 | H7: 40 | I7: 40 | J7: map:data/GZ_Curves.json
A8: Stage 5 | B8: Y | C8: PASS | D8: 0.23561945 | E8: 0.41887902 | F8: 0.18325957 | G8: 1.2 | H8: 40 | I8: 40 | J8: map:data/GZ_Curves.json
A9: Stage 5_PreBallast | B9: Y | C9: PASS | D9: 0.31415927 | E9: 0.55850536 | F9: 0.2443461 | G9: 1.6 | H9: 40 | I9: 40 | J9: map:data/GZ_Curves.json
A10: Stage 6A_Critical (Opt C) | B10: Y | C10: PASS | D10: 0.31415927 | E10: 0.55850536 | F10: 0.2443461 | G10: 1.6 | H10: 40 | I10: 40 | J10: map:data/GZ_Curves.json
A11: Stage 6C_TotalMassOpt | B11: N | C11: FAIL | J11: GZ curve points (provide data/GZ/<stage>.json or data/GZ_Curves.json)
A12: Stage 6C | B12: Y | C12: PASS | D12: 0.23561945 | E12: 0.41887902 | F12: 0.18325957 | G12: 1.2 | H12: 40 | I12: 40 | J12: map:data/GZ_Curves.json
A13: Stage 7 | B13: Y | C13: PASS | D13: 0.23561945 | E13: 0.41887902 | F13: 0.18325957 | G13: 1.2 | H13: 40 | I13: 40 | J13: map:data/GZ_Curves.json

Sheet MWS_Acceptance_Criteria
A1: MWS / Harbour Master – Acceptance Criteria Gate (data-driven)
A3: Stage | B3: Available | C3: PASS | D3: Missing | E3: Checks (key: value op limit)
A4: Stage 1 | B4: N | C4: FAIL | D4: WindMax, HsMax, CurrentMax, UKCMin, RampAngleMax, AftDraftMax | E4: FwdDraftMax:3.268146718146718 <= 2.7
A5: Stage 2 | B5: N | C5: FAIL | D5: WindMax, HsMax, CurrentMax, UKCMin, RampAngleMax, AftDraftMax | E5: FwdDraftMax:3.4239841222483425 <= 2.7
A6: Stage 3 | B6: N | C6: FAIL | D6: WindMax, HsMax, CurrentMax, UKCMin, RampAngleMax, AftDraftMax | E6: FwdDraftMax:3.4239841222483425 <= 2.7
A7: Stage 4 | B7: N | C7: FAIL | D7: WindMax, HsMax, CurrentMax, UKCMin, RampAngleMax, AftDraftMax | E7: FwdDraftMax:3.4080846147109654 <= 2.7
A8: Stage 5 | B8: N | C8: FAIL | D8: WindMax, HsMax, CurrentMax, UKCMin, RampAngleMax, AftDraftMax | E8: FwdDraftMax:3.4080846147109654 <= 2.7
A9: Stage 5_PreBallast | B9: N | C9: FAIL | D9: WindMax, HsMax, CurrentMax, UKCMin, RampAngleMax, AftDraftMax | E9: FwdDraftMax:1.8340754705882354 <= 2.7
A10: Stage 6A_Critical (Opt C) | B10: N | C10: FAIL | D10: WindMax, HsMax, CurrentMax, UKCMin, RampAngleMax, AftDraftMax | E10: FwdDraftMax:1.6606271176470588 <= 2.7
A11: Stage 6C_TotalMassOpt | B11: N | C11: FAIL | D11: WindMax, HsMax, CurrentMax, UKCMin, RampAngleMax, AftDraftMax | E11: FwdDraftMax:3.684904557482417 <= 2.7
A12: Stage 6C | B12: N | C12: FAIL | D12: WindMax, HsMax, CurrentMax, UKCMin, RampAngleMax, AftDraftMax | E12: FwdDraftMax:3.684904557482417 <= 2.7
A13: Stage 7 | B13: N | C13: FAIL | D13: WindMax, HsMax, CurrentMax, UKCMin, RampAngleMax, AftDraftMax | E13: FwdDraftMax:3.268146718146718 <= 2.7

Sheet RORO_Structural_Gate
A1: Structural Gate – Deck / Ramp / Point Load (data-driven)
A3: Stage | B3: Available | C3: PASS | D3: Missing | E3: Checks (key: value op limit)
A4: Stage 1 | B4: N | C4: FAIL | D4: DeckPressure, PointLoad, RampPlate
A5: Stage 2 | B5: N | C5: FAIL | D5: DeckPressure, PointLoad, RampPlate
A6: Stage 3 | B6: N | C6: FAIL | D6: DeckPressure, PointLoad, RampPlate
A7: Stage 4 | B7: N | C7: FAIL | D7: DeckPressure, PointLoad, RampPlate
A8: Stage 5 | B8: N | C8: FAIL | D8: DeckPressure, PointLoad, RampPlate
A9: Stage 5_PreBallast | B9: N | C9: FAIL | D9: DeckPressure, PointLoad, RampPlate
A10: Stage 6A_Critical (Opt C) | B10: N | C10: FAIL | D10: DeckPressure, PointLoad, RampPlate
A11: Stage 6C_TotalMassOpt | B11: N | C11: FAIL | D11: DeckPressure, PointLoad, RampPlate
A12: Stage 6C | B12: N | C12: FAIL | D12: DeckPressure, PointLoad, RampPlate
A13: Stage 7 | B13: N | C13: FAIL | D13: DeckPressure, PointLoad, RampPlate

Sheet CSM_Trace
A1: CSM Traceability – Inputs used for securing (CSS Code / CSM)
A3: Available | B3: Y
A4: Basis | B4: Securing_Input.json
A5: Missing
A7: id | B7: type | C7: wll_t | D7: qty | E7: remarks
A8: L01 | B8: chain | C8: 20 | D8: 0 | E8: TO_BE_FILLED
A9: L02 | B9: wire | C9: 15 | D9: 0 | E9: TO_BE_FILLED

Sheet MWS_Pack_Index
A1: MWS-ready Pack Index (B+) – Evidence & Submittals Checklist
A3: Item | B3: Owner | C3: Status | D3: Remarks / Where to attach
A4: Approved Stability Booklet / Hydro Tables | B4: Vessel Owner | C4: REQ | D4: Hydro_Table_Engineering.json + GM_Min_Curve.json
A5: GZ Curve (per stage) for IS Code check | B5: Naval Arch. | C5: REQ | D5: data/GZ/<stage>.json or data/GZ_Curves.json
A6: Cargo Securing Manual (CSM) / Lashing Plan | B6: 3PL / Marine | C6: REQ | D6: Securing_Input.json (trace) + drawings
A7: Ramp Plate Certificate / Deck Load Chart | B7: Port / Vessel | C7: REQ | D7: Structural_Limits.json + cert scan
A8: Method Statement / Operation Manual | B8: Contractor | C8: REQ | D8: Attach in submission pack
A9: Weather Window / Alpha factor basis | B9: MWS | C9: REQ | D9: Acceptance_Criteria.json + forecast tie-out
A10: Tow / Mooring / Pilotage plan (AGI) | B10: Marine Ops | C10: REQ | D10: Attach drawings + approvals
A11: Evidence photos/videos + timestamps | B11: Marine Ops | C11: REQ | D11: 15+ photos tagged per site rule

Sheet Ballast_Tanks
A1: TankName | B1: x_from_mid_m | C1: max_t | D1: SG | E1: use_flag | F1: air_vent_mm
A2: FWB1.P | B2: -27.37 | C2: 50.57 | D2: 1 | E2: Y | F2: 80
A3: FWB1.S | B3: -27.37 | C3: 50.57 | D3: 1 | E3: Y | F3: 80
A4: FWB2.P | B4: -19.89 | C4: 109.98 | D4: 1 | E4: Y | F4: 80
A5: FWB2.S | B5: -19.89 | C5: 109.98 | D5: 1 | E5: Y | F5: 80
A6: FWCARGO1.P | B6: -12.6 | C6: 148.35 | D6: 1 | E6: N | F6: 125
A7: FWCARGO1.S | B7: -12.6 | C7: 148.35 | D7: 1 | E7: N | F7: 125
A8: FWCARGO2.P | B8: -5.1 | C8: 148.36 | D8: 1 | E8: N | F8: 125
A9: FWCARGO2.S | B9: -5.1 | C9: 148.36 | D9: 1 | E9: N | F9: 125

Sheet CONST_TANKS
B1: CONST_TANKS – Permanent Loads (Fuel/FW)
A3: Tank | B3: Type | C3: Weight_t | D3: LCG_m | E3: FSM_mt_m | F3: Remarks
A4: DO.P | B4: Fuel | C4: 3.05 | D4: 11.25 | E4: 0.34 | F4: default
A5: DO.S | B5: Fuel | C5: 3.05 | D5: 11.25 | E5: 0.34 | F5: default
A6: LRFO.P | B6: Fuel | C6: 154.89 | D6: 19.5 | E6: 133.89 | F6: default
A7: LRFO.S | B7: Fuel | C7: 154.89 | D7: 19.5 | E7: 133.89 | F7: default
A8: FW1.P | B8: FreshWater | C8: 23.16 | D8: 5.98 | E8: 1.15 | F8: default
A9: FW1.S | B9: FreshWater | C9: 23.16 | D9: 5.98 | E9: 1.15 | F9: default
A10: FW2.P | B10: FreshWater | C10: 13.92 | D10: 0.12 | E10: 3.71 | F10: default
A11: FW2.S | B11: FreshWater | C11: 13.92 | D11: 0.12 | E11: 3.71 | F11: default
C12: Total Weight [t] | E12: Total FSM [mt·m]
C13: =SUM(C4:C11) | E13: =SUM(E4:E11)

Sheet Hydro_Table
A1: Disp_t | B1: Tmean_m | C1: Trim_m | D1: GM_m | E1: Draft_FWD | F1: Draft_AFT | G1: LCF_m_from_midship | H1: MCTC_t_m_per_cm | I1: TPC_t_per_cm | J1: GM_min_m | K1: LCF_m | L1: KM_m
A2: 2524.4 | B2: 3 | C2: 0 | D2: 8.45 | E2: 3 | F2: 3 | G2: 0.76 | H2: 38.3 | I2: 10.2 | J2: 1.5 | K2: 0.76 | L2: 12.341
A3: 2626.6 | B3: 3.1 | C3: 0 | D3: 8.18 | E3: 3.1 | F3: 3.1 | G3: 0.76 | H3: 39.1 | I3: 10.3 | J3: 1.5 | K3: 0.76 | L3: 12.072
A4: 2729.4 | B4: 3.2 | C4: 0 | D4: 7.93 | E4: 3.2 | F4: 3.2 | G4: 0.76 | H4: 39.9 | I4: 10.3 | J4: 1.5 | K4: 0.76 | L4: 11.823
A5: 2833 | B5: 3.3 | C5: 0 | D5: 7.7 | E5: 3.3 | F5: 3.3 | G5: 0.76 | H5: 40.7 | I5: 10.4 | J5: 1.5 | K5: 0.76 | L5: 11.592
A6: 2937.5 | B6: 3.4 | C6: 0 | D6: 7.49 | E6: 3.4 | F6: 3.4 | G6: 0.76 | H6: 41.6 | I6: 10.5 | J6: 1.5 | K6: 0.76 | L6: 11.378
A7: 3042.6 | B7: 3.5 | C7: 0 | D7: 7.29 | E7: 3.5 | F7: 3.5 | G7: 0.76 | H7: 42.4 | I7: 10.6 | J7: 1.5 | K7: 0.76 | L7: 11.18
A8: 3148.6 | B8: 3.6 | C8: 0 | D8: 7.1 | E8: 3.6 | F8: 3.6 | G8: 0.76 | H8: 43.3 | I8: 10.6 | J8: 1.5 | K8: 0.76 | L8: 10.995
A9: 3255.3 | B9: 3.7 | C9: 0 | D9: 6.93 | E9: 3.7 | F9: 3.7 | G9: 0.76 | H9: 44.2 | I9: 10.7 | J9: 1.5 | K9: 0.76 | L9: 10.824
A10: 3362 | B10: 3.8 | C10: 0 | D10: 6.76 | E10: 3.8 | F10: 3.8 | G10: 0.76 | H10: 45.1 | I10: 10.8 | J10: 1.5 | K10: 0.76 | L10: 10.66
A11: 3469 | B11: 3.9 | C11: 0 | D11: 6.59 | E11: 3.9 | F11: 3.9 | G11: 0.76 | H11: 46 | I11: 10.9 | J11: 1.5 | K11: 0.76 | L11: 10.5

Sheet Frame_to_x_Table
A1: Fr | B1: x_from_mid_m | C1: 비고
A2: 0 | B2: 30.15 | C2: Ramp hinge
A3: 0.5 | B3: 29.65
A4: 1 | B4: 29.15
A5: 1.5 | B5: 28.65
A6: 2 | B6: 28.15
A7: 2.5 | B7: 27.65
A8: 3 | B8: 27.15
A9: 3.5 | B9: 26.65
A10: 4 | B10: 26.15
A11: 4.5 | B11: 25.65
A12: 5 | B12: 25.15
A13: 5.5 | B13: 24.65
A14: 6 | B14: 24.15
... A77: 37.5 | B77: -7.35
A78: 38 | B78: -7.85 | C78: 6B ramp 중간
A79: 38.5 | B79: -8.35
A80: 39 | B80: -8.85
A81: 39.5 | B81: -9.35
